Workbook

Sheet Modelos actuales
A1: id_country | B1: country | C1: iteration_date | D1: n_model | E1: model_name | F1: mean_stake_home | G1: mean_stake_draw | H1: mean_stake_away | I1: mean_stake | J1: Error test | K1: Error prod | L1: Var error
A2: 6 | B2: argentina | C2: 45694 | D2: 1 | E2: LogisticRegression
A3: 167 | B3: usa
A4: 48 | B4: england | C4: 45784 | D4: 93 | E4: RandomForestClassifier | I4: =AVERAGE(F4:H4) -> #DIV/0! | L4: =(K4-J4)/J4 -> #DIV/0!
A5: 55 | B5: france | C5: 45784 | D5: 73 | E5: XGBClassifier | I5: =AVERAGE(F5:H5) -> #DIV/0! | L5: =(K5-J5)/J5 -> #DIV/0!
A6: 59 | B6: germany | C6: 45785 | D6: 16 | E6: RandomForestClassifier | I6: =AVERAGE(F6:H6) -> #DIV/0! | L6: =(K6-J6)/J6 -> #DIV/0!
A7: 77 | B7: italy | C7: 45785 | D7: 45 | E7: RandomForestClassifier | I7: =AVERAGE(F7:H7) -> #DIV/0! | L7: =(K7-J7)/J7 -> #DIV/0!
A8: 148 | B8: spain | C8: 45784 | D8: 67 | E8: RandomForestClassifier | I8: =AVERAGE(F8:H8) -> #DIV/0! | L8: =(K8-J8)/J8 -> #DIV/0!

Sheet Sheet35
P3: Usando n_wins y esas | Q3: Sin n_wins y esas | S3: con escalado | T3: sin escalado | V3: decay_rate=0 | W3: decay_rate=0.2 | Y3: con_val_players | Z3: sin_val_players | AB3: usando 'S2G', 'xS2G', "SOG2S", | AC3: sin | AE3: Con ELO | AF3: sin ELO | AH3: porc_nan=0.2 | AI3: porc_nan=0.35 | AJ3: porc_nan=0.7 | AL3: =MIN(AL6:AL1497) -> -0.44 | AM3: =MIN(AM6:AM1497) -> -0.49 | AN3: =MIN(AN6:AN1497) -> -0.48
K4: =AVERAGE(K6:K65) -> 44.30225 | L4: =AVERAGE(L6:L65) -> 44.795167 | M4: =AVERAGE(M6:M65) -> 44.155833 | O4: =AVERAGE(O6:O1497) -> 45.017833 | P4: =AVERAGE(P6:P1497) -> 43.772833 | Q4: =AVERAGE(Q6:Q1497) -> 43.498 | S4: =AVERAGE(S6:S1497) -> 43.772833 | T4: =AVERAGE(T6:T1497) -> 43.791667 | V4: =AVERAGE(V6:V1497) -> 44.6275 | W4: =AVERAGE(W6:W1497) -> 44.9325 | Y4: =AVERAGE(Y6:Y1497) -> 44.619667 | Z4: =AVERAGE(Z6:Z1497) -> 44.6275 | AB4: =AVERAGE(AB6:AB1497) -> 44.6275 | AC4: =AVERAGE(AC6:AC1497) -> 44.3825 | AE4: =AVERAGE(AE6:AE1497) -> 44.6275 | AF4: =AVERAGE(AF6:AF1497) -> 43.722167 | AH4: =AVERAGE(AH6:AH1497) -> 43.2375 | AI4: =AVERAGE(AI6:AI1497) -> 44.6275 | AJ4: =AVERAGE(AJ6:AJ1497) -> 42.620625 | AK4: =AVERAGE(AK6:AK1497) -> 44.592 | AL4: =AVERAGE(AL6:AL1497) -> -0.13164 | AM4: =AVERAGE(AM6:AM1497) -> -0.1838 | AN4: =AVERAGE(AN6:AN1497) -> -0.1339
P5: =STDEV(P6:P1497) -> 3.9028221 | Q5: =STDEV(Q6:Q1497) -> 5.8680317 | S5: =STDEV(S6:S1497) -> 3.9028221 | T5: =STDEV(T6:T1497) -> 4.6210972 | V5: =STDEV(V6:V1497) -> 4.4672498 | W5: =STDEV(W6:W1497) -> 4.1612488 | Y5: =STDEV(Y6:Y1497) -> 3.6374404 | Z5: =STDEV(Z6:Z1497) -> 4.4672498 | AB5: =STDEV(AB6:AB1497) -> 4.4672498 | AC5: =STDEV(AC6:AC1497) -> 4.228009 | AE5: =STDEV(AE6:AE1497) -> 4.4672498 | AF5: =STDEV(AF6:AF1497) -> 4.1254983 | AH5: =STDEV(AH6:AH1497) -> 4.6913822 | AI5: =STDEV(AI6:AI1497) -> 4.4672498 | AJ5: =STDEV(AJ6:AJ1497) -> 4.5873389 | AK5: =STDEV(AK6:AK1497) -> 3.8033332 | AL5: =STDEV(AL6:AL1497) -> 0.11676549 | AM5: =STDEV(AM6:AM1497) -> 0.12214647 | AN5: =STDEV(AN6:AN1497) -> 0.14105587
B6: (1) Ver si el nuevo train con los cambios es bueno o no comparandolo con los test del anterior train. Si es bueno: - Commit de cambios en main y mtm. - Documentacion de cambios - Adaptar mnm.py tras cambios en xpath de modelos guardados y por cambio en el flujo (no se si lo afecta pero capaz si). - Entrenar otros paises Si no es bueno: - Guardar cambios en branch aparte y volver a staging como estaba. Probar cambio por cambio de los nuevos e ir implementando de a uno. | K6: 46.3 | L6: 47.32 | M6: 41.97 | O6: 44.77 | P6: 41.54 | Q6: 45.9 | S6: 41.54 | T6: 46.52 | V6: 52.18 | W6: 50.26 | Y6: 48.88 | Z6: 52.18 | AB6: 52.18 | AC6: 38.91 | AE6: 52.18 | AF6: 45.9 | AH6: 50.53 | AI6: 52.18 | AJ6: 43.21 | AK6: 49.48 | AL6: -0.01 | AM6: -0.22 | AN6: -0.29
K7: 44.17 | L7: 50.77 | M7: 48.95 | O7: 48.36 | P7: 47.94 | Q7: 47.21 | S7: 47.94 | T7: 48.48 | V7: 46.21 | W7: 38.91 | Y7: 40.75 | Z7: 46.21 | AB7: 46.21 | AC7: 49.48 | AE7: 46.21 | AF7: 50.32 | AH7: 50.55 | AI7: 46.21 | AJ7: 39.47 | AK7: 51.27 | AL7: -0.23 | AM7: -0.29 | AN7: -0.31
B8: (2) Experimento metricas + bs | K8: 50.03 | L8: 45.63 | M8: 50.34 | O8: 45.11 | P8: 44.26 | Q8: 43.02 | S8: 44.26 | T8: 38.86 | V8: 41.95 | W8: 36.23 | Y8: 40.46 | Z8: 41.95 | AB8: 41.95 | AC8: 43.49 | AE8: 41.95 | AF8: 47.06 | AH8: 42.94 | AI8: 41.95 | AJ8: 39.76 | AK8: 43.86 | AL8: 0.01 | AM8: -0.14 | AN8: -0.05
K9: 41.2 | L9: 33.19 | M9: 40.49 | O9: 35.26 | P9: 44.53 | Q9: 41.6 | S9: 44.53 | T9: 43.53 | V9: 41.55 | W9: 47.64 | Y9: 41.84 | Z9: 41.55 | AB9: 41.55 | AC9: 43.54 | AE9: 41.55 | AF9: 48.6 | AH9: 35.2 | AI9: 41.55 | AJ9: 37.64 | AK9: 40.32 | AL9: -0.1 | AM9: -0.24 | AN9: -0.12
B10: (3) Seguir con paso a paso de: | K10: 48.95 | L10: 38.84 | M10: 51.09 | O10: 36.58 | P10: 42.57 | Q10: 40.34 | S10: 42.57 | T10: 47.62 | V10: 40.5 | W10: 44.46 | Y10: 47.02 | Z10: 40.5 | AB10: 40.5 | AC10: 44.86 | AE10: 40.5 | AF10: 38.96 | AH10: 44.58 | AI10: 40.5 | AJ10: 35.49 | AK10: 45.23 | AL10: 0.08 | AM10: -0.29 | AN10: -0.14
B11: 2025-05-01 | K11: 39.22 | L11: 40.89 | M11: 41.7 | O11: 44.71 | P11: 44.71 | Q11: 35.54 | S11: 44.71 | T11: 39.07 | V11: 44.71 | W11: 38.6 | Y11: 42.56 | Z11: 44.71 | AB11: 44.71 | AC11: 35.48 | AE11: 44.71 | AF11: 44.2 | AH11: 37.18 | AI11: 44.71 | AJ11: 42.28 | AK11: 50.55 | AL11: -0.14 | AM11: -0.07 | AN11: -0.02
B12: 1. comparar codigo de diciembre de 2024 con el actual 2. Feedback del cliente | K12: 48.11 | L12: 48.47 | M12: 51.19 | O12: 42.63 | P12: 39.69 | Q12: 40.64 | S12: 39.69 | T12: 38.23 | V12: 52.97 | W12: 51.9 | Y12: 42.06 | Z12: 52.97 | AB12: 52.97 | AC12: 41.54 | AE12: 52.97 | AF12: 37.93 | AH12: 41.41 | AI12: 52.97 | AJ12: 44.95 | AK12: 42.65 | AL12: -0.01 | AM12: 0.01 | AN12: -0.18
K13: 46.18 | L13: 46.41 | M13: 49.74 | O13: 44.64 | P13: 44.61 | Q13: 46.66 | S13: 44.61 | T13: 46.28 | V13: 42.97 | W13: 42.99 | Y13: 50.81 | Z13: 42.97 | AB13: 42.97 | AC13: 42.59 | AE13: 42.97 | AF13: 41.01 | AH13: 43.15 | AI13: 42.97 | AJ13: 41.32 | AK13: 40.84 | AL13: -0.1 | AM13: -0.34 | AN13: -0.17
K14: 43.76 | L14: 54.18 | M14: 47.24 | O14: 45.41 | P14: 38.26 | Q14: 48.34 | S14: 38.26 | T14: 43.43 | V14: 41.21 | W14: 43.56 | Y14: 47.96 | Z14: 41.21 | AB14: 41.21 | AC14: 47.4 | AE14: 41.21 | AF14: 36.67 | AH14: 38.96 | AI14: 41.21 | AJ14: 43.85 | AK14: 45.28 | AL14: -0.15 | AM14: 0.03 | AN14: -0.22
K15: 51.04 | L15: 43.84 | M15: 37.72 | O15: 38.51 | P15: 42.44 | Q15: 41.93 | S15: 42.44 | T15: 42.44 | V15: 42.53 | W15: 48.78 | Y15: 45.13 | Z15: 42.53 | AB15: 42.53 | AC15: 40.33 | AE15: 42.53 | AF15: 48.11 | AH15: 47.34 | AI15: 42.53 | AJ15: 38.39 | AK15: 49.33 | AL15: -0.04 | AM15: -0.18 | AN15: -0.41
K16: 41.89 | L16: 51.45 | M16: 42.86 | O16: 36.87 | P16: 51 | Q16: 36.67 | S16: 51 | T16: 40.75 | V16: 40.46 | W16: 46.51 | Y16: 43.78 | Z16: 40.46 | AB16: 40.46 | AC16: 49.78 | AE16: 40.46 | AF16: 44.48 | AH16: 47.89 | AI16: 40.46 | AJ16: 42.94 | AK16: 41.96 | AL16: -0.2 | AM16: 0 | AN16: 0.18
K17: 41.45 | L17: 41.74 | M17: 44.33 | O17: 45.97 | P17: 45.97 | Q17: 35.91 | S17: 45.97 | T17: 45.02 | V17: 45.97 | W17: 42.09 | Y17: 39.08 | Z17: 45.97 | AB17: 45.97 | AC17: 41.81 | AE17: 45.97 | AF17: 37.36 | AH17: 39.4 | AI17: 45.97 | AJ17: 36 | AK17: 40.58 | AL17: -0.17 | AM17: -0.12 | AN17: -0.48
K18: 43.59 | L18: 35.99 | M18: 40.19 | O18: 38.31 | P18: 34.47 | Q18: 41.88 | S18: 34.47 | T18: 36.64 | V18: 52.63 | W18: 49.62 | Y18: 36.82 | Z18: 52.63 | AB18: 52.63 | AC18: 42.89 | AE18: 52.63 | AF18: 36.46 | AH18: 52.47 | AI18: 52.63 | AJ18: 38.13 | AK18: 41.68 | AL18: 0.01 | AM18: -0.16 | AN18: -0.18
K19: 40.25 | L19: 49.93 | M19: 47.22 | O19: 52.16 | P19: 46.87 | Q19: 48.37 | S19: 46.87 | T19: 49.28 | V19: 53.24 | W19: 48.21 | Y19: 42.39 | Z19: 53.24 | AB19: 53.24 | AC19: 52.46 | AE19: 53.24 | AF19: 47.97 | AH19: 48.59 | AI19: 53.24 | AJ19: 40.62 | AK19: 45.03 | AL19: -0.08 | AM19: -0.14 | AN19: -0.43
K20: 50.18 | L20: 48.19 | M20: 45.91 | O20: 50.26 | P20: 46.2 | Q20: 48.29 | S20: 46.2 | T20: 49.26 | V20: 48.36 | W20: 39.65 | Y20: 43.63 | Z20: 48.36 | AB20: 48.36 | AC20: 53.75 | AE20: 48.36 | AF20: 48.49 | AH20: 42.52 | AI20: 48.36 | AJ20: 38.1 | AK20: 40.42 | AL20: 0 | AM20: -0.18 | AN20: 0.12
K21: 52.92 | L21: 45.63 | M21: 49.34 | O21: 43.8 | P21: 41.64 | Q21: 42.2 | S21: 41.64 | T21: 44.35 | V21: 35.83 | W21: 39.07 | Y21: 41.59 | Z21: 35.83 | AB21: 35.83 | AC21: 43.18 | AE21: 35.83 | AF21: 40.37 | AH21: 44.68 | AI21: 35.83 | AJ21: 42.11 | AK21: 38 | AL21: -0.08 | AM21: -0.03 | AN21: -0.11
K22: 43.93 | L22: 40.63 | M22: 38.88 | O22: 43.74 | P22: 44.46 | Q22: 43.1 | S22: 44.46 | T22: 43.9 | V22: 41.77 | W22: 43.81 | Y22: 43.48 | Z22: 41.77 | AB22: 41.77 | AC22: 44.76 | AE22: 41.77 | AF22: 41.87 | AH22: 45.03 | AI22: 41.77 | AJ22: 43.88 | AK22: 47.11 | AL22: -0.18 | AM22: -0.15 | AN22: -0.17
K23: 35.68 | L23: 39.71 | M23: 40.78 | O23: 41.53 | P23: 41.53 | Q23: 39.7 | S23: 41.53 | T23: 38.32 | V23: 41.53 | W23: 39.59 | Y23: 40.23 | Z23: 41.53 | AB23: 41.53 | AC23: 44.65 | AE23: 41.53 | AF23: 41.79 | AH23: 42.96 | AI23: 41.53 | AJ23: 39.47 | AK23: 46.48 | AL23: -0.35 | AM23: -0.29 | AN23: -0.21
K24: 40.88 | L24: 51.57 | M24: 45.61 | O24: 45.43 | P24: 45.08 | Q24: 46.66 | S24: 45.08 | T24: 46.01 | V24: 51.01 | W24: 39.94 | Y24: 45.16 | Z24: 51.01 | AB24: 51.01 | AC24: 40.63 | AE24: 51.01 | AF24: 35.31 | AH24: 36.73 | AI24: 51.01 | AJ24: 52.45 | AK24: 47.48 | AL24: -0.27 | AM24: -0.26 | AN24: -0.13
K25: 45.29 | L25: 44.85 | M25: 51.24 | O25: 45.62 | P25: 43.93 | Q25: 50.82 | S25: 43.93 | T25: 43.93 | V25: 43.02 | W25: 42.54 | Y25: 49.3 | Z25: 43.02 | AB25: 43.02 | AC25: 46.07 | AE25: 43.02 | AF25: 47.58 | AH25: 49.68 | AI25: 43.02 | AJ25: 35.06 | AK25: 44.29 | AL25: -0.23 | AM25: -0.39 | AN25: -0.26
K26: 48.63 | L26: 49.34 | M26: 45.46 | O26: 46.89 | P26: 42.8 | Q26: 41.24 | S26: 42.8 | T26: 46.41 | V26: 48.3 | W26: 51.92 | Y26: 44.83 | Z26: 48.3 | AB26: 48.3 | AC26: 44.85 | AE26: 48.3 | AF26: 45.19 | AH26: 45.02 | AI26: 48.3 | AJ26: 39.5 | AL26: 0.05 | AM26: -0.1 | AN26: -0.07
K27: 44.47 | L27: 47.7 | M27: 43.78 | O27: 44.69 | P27: 41.07 | Q27: 34.19 | S27: 41.07 | T27: 43.13 | V27: 44.64 | W27: 45.15 | Y27: 44.64 | Z27: 44.64 | AB27: 44.64 | AC27: 42.25 | AE27: 44.64 | AF27: 43.85 | AH27: 40.56 | AI27: 44.64 | AJ27: 43.62 | AL27: 0.02 | AM27: -0.43 | AN27: -0.26
K28: 40.31 | L28: 42.99 | M28: 46.6 | O28: 44.22 | P28: 45.71 | Q28: 50.08 | S28: 45.71 | T28: 44.15 | V28: 43.23 | W28: 41.82 | Y28: 45.5 | Z28: 43.23 | AB28: 43.23 | AC28: 46.5 | AE28: 43.23 | AF28: 39.5 | AH28: 43.6 | AI28: 43.23 | AJ28: 38.67 | AL28: -0.12 | AM28: -0.08 | AN28: 0.13
K29: 36.29 | L29: 32.9 | M29: 39.92 | O29: 43.03 | P29: 43.03 | Q29: 40.38 | S29: 43.03 | T29: 37.33 | V29: 43.03 | W29: 40.19 | Y29: 39.92 | Z29: 43.03 | AB29: 43.03 | AC29: 40.8 | AE29: 43.03 | AF29: 40.8 | AH29: 39.88 | AI29: 43.03 | AJ29: 34.99 | AL29: -0.11 | AM29: -0.34 | AN29: -0.14
K30: 44.48 | L30: 39.88 | M30: 47.38 | O30: 41.78 | P30: 42.32 | Q30: 40.71 | S30: 42.32 | T30: 20.8 | V30: 42.86 | W30: 45.16 | Y30: 45.01 | Z30: 42.86 | AB30: 42.86 | AC30: 46.3 | AE30: 42.86 | AF30: 42.11 | AH30: 47.35 | AI30: 42.86 | AJ30: 40.43 | AL30: -0.12 | AM30: -0.15 | AN30: -0.04
K31: 50.66 | L31: 45.48 | M31: 50.55 | O31: 45.57 | P31: 42.48 | Q31: 51.95 | S31: 42.48 | T31: 41.71 | V31: 49.5 | W31: 49.32 | Y31: 48.04 | Z31: 49.5 | AB31: 49.5 | AC31: 41.96 | AE31: 49.5 | AF31: 43.55 | AH31: 49.61 | AI31: 49.5 | AJ31: 39.52 | AL31: -0.16 | AM31: -0.42 | AN31: -0.35
K32: 42.02 | L32: 54.91 | M32: 48.95 | O32: 46.05 | P32: 44.86 | Q32: 44.52 | S32: 44.86 | T32: 48.57 | V32: 48.09 | W32: 47.77 | Y32: 50.64 | Z32: 48.09 | AB32: 48.09 | AC32: 42.21 | AE32: 48.09 | AF32: 40.68 | AH32: 44.9 | AI32: 48.09 | AJ32: 42.08 | AL32: -0.22 | AM32: -0.13 | AN32: -0.05
K33: 43.37 | L33: 33.82 | M33: 44.34 | O33: 46.29 | P33: 43.04 | Q33: 36.74 | S33: 43.04 | T33: 34.68 | V33: 46.71 | W33: 41.28 | Y33: 45.88 | Z33: 46.71 | AB33: 46.71 | AC33: 48.31 | AE33: 46.71 | AF33: 40 | AH33: 41.09 | AI33: 46.71 | AJ33: 39.9 | AL33: -0.31 | AM33: -0.3 | AN33: -0.25
K34: 45.77 | L34: 43.46 | M34: 46.35 | O34: 47.45 | P34: 44.08 | Q34: 40.07 | S34: 44.08 | T34: 44.66 | V34: 33.71 | W34: 42.66 | Y34: 47.59 | Z34: 33.71 | AB34: 33.71 | AC34: 34.69 | AE34: 33.71 | AF34: 42.41 | AH34: 36.74 | AI34: 33.71 | AJ34: 44.14 | AL34: 0.08 | AM34: -0.07 | AN34: -0.05
K35: 48.31 | L35: 45.15 | M35: 46.08 | O35: 43.18 | P35: 43.18 | Q35: 44.26 | S35: 43.18 | T35: 41.6 | V35: 43.18 | W35: 42.71 | Y35: 43.18 | Z35: 43.18 | AB35: 43.18 | AC35: 46.97 | AE35: 43.18 | AF35: 43.18 | AH35: 41.05 | AI35: 43.18 | AJ35: 43.22 | AL35: -0.03 | AM35: -0.24 | AN35: -0.18
K36: 38.13 | L36: 48.98 | M36: 20.8 | O36: 53.09 | P36: 41.4 | Q36: 43.15 | S36: 41.4 | T36: 46.91 | V36: 50.71 | W36: 45.74 | Y36: 36.83 | Z36: 50.71 | AB36: 50.71 | AC36: 39.95 | AE36: 50.71 | AF36: 44.8 | AH36: 41.63 | AI36: 50.71 | AJ36: 37.01 | AL36: -0.1 | AM36: -0.23 | AN36: 0.05
K37: 40.27 | L37: 46.62 | M37: 50.56 | O37: 42.04 | P37: 43.85 | Q37: 53.21 | S37: 43.85 | T37: 50.79 | V37: 46.44 | W37: 48.28 | Y37: 45.41 | Z37: 46.44 | AB37: 46.44 | AC37: 43.52 | AE37: 46.44 | AF37: 49.63 | AH37: 54.9 | AI37: 46.44 | AJ37: 50.54 | AL37: -0.07 | AM37: -0.37 | AN37: -0.06
... K45: 44.08 | L45: 54.67 | M45: 40.43 | O45: 45.31 | P45: 38.68 | Q45: 40.69 | S45: 38.68 | T45: 41.21 | V45: 41.35 | W45: 49.88 | Y45: 49.91 | Z45: 41.35 | AB45: 41.35 | AC45: 38.58 | AE45: 41.35 | AF45: 40.52 | AH45: 36.11 | AI45: 41.35 | AJ45: 42.12 | AL45: -0.24 | AM45: -0.25 | AN45: -0.29
L46: 38.47 | M46: 43.94 | O46: 38.52 | P46: 44.15 | Q46: 47.39 | S46: 44.15 | T46: 46.34 | V46: 46.11 | W46: 49.46 | Y46: 49.08 | Z46: 46.11 | AB46: 46.11 | AC46: 46.99 | AE46: 46.11 | AF46: 40.34 | AH46: 41.26 | AI46: 46.11 | AJ46: 44.02 | AL46: -0.03 | AM46: -0.12 | AN46: -0.22
L47: 42.74 | M47: 38.25 | O47: 49.34 | P47: 49.34 | Q47: 45.16 | S47: 49.34 | T47: 50.93 | V47: 49.34 | W47: 47.09 | Y47: 49.98 | Z47: 49.34 | AB47: 49.34 | AC47: 46.56 | AE47: 49.34 | AF47: 41.66 | AH47: 42.49 | AI47: 49.34 | AJ47: 40.48 | AL47: -0.21 | AM47: -0.32 | AN47: -0.39
L48: 43.8 | M48: 44.67 | O48: 50.9 | P48: 37.69 | Q48: 48.06 | S48: 37.69 | T48: 46.03 | V48: 40.31 | W48: 41.03 | Y48: 43.44 | Z48: 40.31 | AB48: 40.31 | AC48: 55.36 | AE48: 40.31 | AF48: 48.19 | AH48: 48.92 | AI48: 40.31 | AJ48: 53.9 | AL48: -0.15 | AM48: 0.02 | AN48: 0.04
L49: 51.01 | M49: 49.58 | O49: 53.21 | P49: 43.05 | Q49: 45.52 | S49: 43.05 | T49: 47.63 | V49: 44.38 | W49: 48.1 | Y49: 44.66 | Z49: 44.38 | AB49: 44.38 | AC49: 49.26 | AE49: 44.38 | AF49: 54.06 | AH49: 45.8 | AI49: 44.38 | AJ49: 48.46 | AL49: -0.24 | AM49: -0.14 | AN49: -0.22
...

Sheet Modelo semana 24
A2: 48 | B2: england | C2: 45679 | D2: 395 | E2: LogisticRegression | F2: 58 | K2: 2 | L2: 153.7 | M2: 3507.81 | N2: 30 | P2: 22.822446 | Q2: 9
A3: 55 | B3: france | C3: 45679 | D3: 724 | E3: LogisticRegression | F3: 61 | K3: 7 | L3: 174.21 | M3: 1825.81 | N3: 30 | P3: 10.480512 | Q3: 9
A4: 59 | B4: germany | C4: 45680 | D4: 1051 | E4: LogisticRegression | F4: 62 | K4: 3 | L4: 171.72 | M4: 5053.56 | N4: 25 | P4: 29.429071 | Q4: 7.5
A5: 77 | B5: italy | C5: 45677 | D5: 931 | E5: LogisticRegression | F5: 60 | K5: 11 | L5: 190.1 | M5: =2.59+ 1339.47+ 236.53 -> 1578.59 | N5: 40 | P5: =M5/L5 -> 8.3039979
A6: 148 | B6: spain | C6: 45677 | D6: 112 | E6: LogisticRegression | L6: 127.26 | M6: =1920.79+ 729.18+ -17.44 -> 2632.53 | N6: 40 | P6: =M6/L6 -> 20.686233
E11: deberia cambiar el modelo en: ENG y en SPA | L11: Cambio | M11: eng | N11: SPA
E12: No deberia cambiar el modelo en: ITA y GER. | L12: No cambio | M12: GER | N12: ITA
A16: 48 | B16: england | C16: 45679 | D16: 1363 | E16: LogisticRegression | F16: 57.521368 | K16: 6 | L16: 127.72 | M16: 958.71 | N16: 40 | P16: 7.506342 | Q16: 12
A17: 55 | B17: france | C17: 45679 | D17: 724 | E17: LogisticRegression | F17: 57.762697 | K17: 7 | L17: 174.21 | M17: 1825.81 | N17: 30 | P17: 10.480512 | Q17: 9
A18: 59 | B18: germany | C18: 45680 | D18: 935 | E18: LogisticRegression | F18: 61.814767 | K18: 5 | L18: 149.66 | M18: 8422.4 | P18: 56.276894 | Q18: 0
A19: 77 | B19: italy | C19: 45677 | D19: 47 | E19: LogisticRegression | F19: 60.756365 | K19: 12 | L19: 152.96 | M19: 2356.64 | N19: 60 | P19: 15.406904 | Q19: 18
A20: 148 | B20: spain | C20: 45677 | D20: 1475 | E20: LogisticRegression | F20: 56.41732 | K20: 7 | L20: 101.46 | M20: 795.72 | N20: 30 | P20: 7.8426966 | Q20: 9
C24: Que hubera seleccionado con el nuevo metodo en el entrenamiento anterior y como me hubiera ido?
C25: f1_score
C26: test_accuracy
C27: nueva seleccion (n_metric=1)
C28: nueva seleccion con ea
C30: ESTA MAL HECHO ESTO? ESTOY ANALIZANDOLO SIN EA....
C31: SPAIN | L31: ITA | Q31: FRA | Z31: GER | AH31: ENG
C32: 1243 | D32: 52 | E32: 1146 | F32: 860 | G32: 1444 | H32: 1257 | I32: 408 | J32: 1146 | L32: 1494 | M32: 1339 | N32: 1338 | O32: 1359 | Q32: 916 | R32: 176 | S32: 364 | T32: 734 | U32: 807 | V32: 806 | W32: 1375 | X32: 808 | Z32: 565 | AA32: 44 | AB32: 56 | AC32: 728 | AD32: 795 | AE32: 59 | AF32: 1447 | AH32: 38 | AI32: 217 | AJ32: 229 | AK32: 245 | AL32: 930 | AM32: 447 | AN32: 561 | AO32: 44 | AP32: 194
C33: =SUM(C34:C47) -> 2.25 | D33: =SUM(D34:D47) -> -12.37 | E33: =SUM(E34:E47) -> -24.21 | F33: =SUM(F34:F47) -> 11.79 | G33: =SUM(G34:G47) -> -15.52 | H33: =SUM(H34:H47) -> -8.53 | I33: =SUM(I34:I47) -> -4.23 | J33: =SUM(J34:J47) -> -24.21 | L33: =SUM(L34:L51) -> -1.5 | M33: =SUM(M34:M47) -> 24.31 | N33: =SUM(N34:N47) -> 31.5 | O33: =SUM(O34:O47) -> -5.84 | Q33: =SUM(Q34:Q51) -> -7.31 | R33: =SUM(R34:R47) -> -20.51 | S33: =SUM(S34:S47) -> -10.26 | T33: =SUM(T34:T47) -> 7.35 | U33: =SUM(U34:U47) -> 17.63 | V33: =SUM(V34:V47) -> 4.01 | W33: =SUM(W34:W47) -> -18.07 | Z33: =SUM(Z34:Z101) -> -14.05 | AA33: =SUM(AA34:AA101) -> 18.35 | AB33: =SUM(AB34:AB101) -> 17.99 | AC33: =SUM(AC34:AC101) -> 13.54 | AD33: =SUM(AD34:AD101) -> -12.75 | AE33: =SUM(AE34:AE101) -> 2 | AF33: =SUM(AF34:AF101) -> 22.18 | AH33: =SUM(AH34:AH49) -> 4 | AI33: =SUM(AI34:AI49) -> -23.73 | AJ33: =SUM(AJ34:AJ49) -> -49.24 | AK33: =SUM(AK34:AK49) -> -59.85 | AL33: =SUM(AL34:AL49) -> 16.48 | AM33: =SUM(AM34:AM49) -> 1.43 | AN33: =SUM(AN34:AN49) -> -17.53 | AO33: =SUM(AO34:AO49) -> -19.7
C34: 5.02 | D34: -4.03 | E34: -4.1 | F34: 5.45 | G34: 4.25 | H34: 5.13 | I34: 5.13 | J34: -4.1 | L34: -4.2 | M34: -5.95 | N34: -4.77 | Q34: -4.13 | R34: -4.63 | S34: -4.23 | T34: -3.89 | U34: -3.73 | V34: -4.14 | W34: -4.94 | Z34: 1.43 | AA34: 1.9 | AB34: 1.9 | AC34: 1.94 | AD34: 1.93 | AE34: 1.88 | AF34: 1.5 | AH34: 14.41 | AI34: -6.68 | AJ34: -6.12 | AK34: -5.47 | AL34: -3.91 | AM34: 4.85 | AN34: -6.38 | AO34: -6.99
C35: -6.5 | D35: -6.7 | E35: -7.34 | F35: -6.92 | G35: -4.1 | H35: -6.16 | I35: -6.38 | J35: -7.34 | L35: 8.48 | M35: -3.97 | N35: -4.28 | Q35: -3.67 | R35: -3.81 | S35: -3.51 | T35: -4.64 | U35: -4 | V35: -4.94 | W35: -4.28 | Z35: -4.37 | AA35: -3.89 | AB35: -4.13 | AC35: 2.84 | AD35: -4.48 | AE35: -4.76 | AF35: -4.74 | AH35: 3.22 | AI35: 2.86 | AJ35: -4.16 | AK35: -4.35 | AL35: 3.8 | AM35: -7.2 | AN35: -7.06 | AO35: -6.43
C36: -5 | D36: -4.67 | E36: -4.61 | F36: -4.73 | G36: -4.07 | H36: -4.46 | I36: -4.36 | J36: -4.61 | L36: -3.96 | M36: -4.58 | N36: -4.4 | Q36: 5.18 | R36: 4.74 | S36: 4.49 | T36: 5.46 | U36: 4.72 | V36: 5.93 | W36: 5.81 | Z36: 5.91 | AA36: 8.73 | AB36: 6.9 | AC36: 5.87 | AD36: 6.2 | AE36: 5.88 | AF36: 10.11 | AH36: -4.23 | AI36: 4.55 | AJ36: -4.34 | AK36: 3.98 | AL36: 3.97 | AM36: 2.68 | AN36: -5.26 | AO36: -6.72
C37: -5.74 | D37: -5.1 | E37: -6.56 | F37: -7.33 | G37: -3.92 | H37: -5.48 | I37: -6.06 | J37: -6.56 | L37: 3.05 | M37: 3.72 | N37: 3.79 | Q37: 3.5 | R37: 3.67 | S37: 3.26 | T37: 3.77 | U37: 3.35 | V37: 3.61 | W37: 3.67 | Z37: -4.19 | AA37: -5.45 | AB37: -4.89 | AC37: 6.75 | AD37: -3.99 | AE37: -3.56 | AF37: -5.75 | AH37: 5.93 | AI37: -5.54 | AJ37: -5.06 | AK37: -5.72 | AL37: 5.92 | AM37: -4.57 | AN37: -4.66 | AO37: -4.28
C38: -3.53 | D38: -5.53 | E38: -4.42 | F38: -4.36 | G38: -3.55 | H38: -3.67 | I38: -4.36 | J38: -4.42 | L38: 3.23 | M38: 4.02 | N38: 4.04 | Q38: -5.17 | R38: -5.11 | S38: -4.67 | T38: -5.46 | U38: -4.61 | V38: -6.09 | W38: -4.06 | Z38: -5.4 | AA38: -4.57 | AB38: 12.62 | AC38: -5.27 | AD38: -4.65 | AE38: -4.74 | AF38: 10.93 | AH38: -4.97 | AI38: -4.29 | AJ38: -4.91 | AK38: -4.51 | AL38: -5.38 | AM38: 5.67 | AN38: 5.83 | AO38: 4.72
C39: 2.94 | D39: 4.1 | E39: 3.28 | F39: 3.1 | G39: 2.95 | H39: 2.94 | I39: 3.04 | J39: 3.28 | L39: -5.06 | M39: -5.52 | N39: -4.97 | Q39: 0.78 | R39: 0.65 | S39: 0.63 | T39: 0.59 | U39: 0.49 | V39: 0.68 | W39: 0.72 | Z39: 0.88 | AA39: 0.99 | AB39: 1.05 | AC39: 1.01 | AD39: 1.1 | AE39: 1.1 | AF39: 1.26 | AH39: 1.62 | AI39: 1.68 | AJ39: 1.99 | AK39: 1.61 | AL39: -5.49
C40: 3.54 | D40: -4.79 | E40: -4.01 | F40: 3.51 | G40: 3.67 | H40: 3.51 | I40: -3.97 | J40: -4.01 | L40: 9.71 | M40: 9.2 | N40: 10.68 | O40: -3.99 | Q40: -4.39 | R40: -3.73 | S40: -3.39 | T40: 10.35 | U40: 10.49 | V40: 11.22 | W40: -5.09 | Z40: -5.16 | AA40: -5.86 | AB40: -6.14 | AC40: -4.26 | AD40: -4.39 | AE40: -4.49 | AF40: -7.84 | AH40: -3.82 | AI40: -4.56 | AJ40: -4.58 | AK40: -4.1 | AL40: 5.23
C41: 1.93 | D41: 1.56 | E41: 2.13 | F41: 2.12 | G41: 1.48 | H41: 1.79 | I41: 1.89 | J41: 2.13 | L41: 4.38 | M41: 5.3 | N41: 5.59 | O41: -6.03 | Q41: -3.63 | R41: -3.58 | S41: -3.52 | T41: -3.79 | U41: 9.56 | V41: -3.82 | W41: 10.73 | Z41: -4.28 | AA41: -5.2 | AB41: -6.18 | AC41: -3.99 | AD41: -4.22 | AE41: -5.61 | AF41: -6.46 | AH41: 1.72 | AI41: 1.78 | AJ41: 1.91 | AK41: -3.61 | AL41: 2.05
C42: -3.39 | D42: -4.03 | E42: -5.23 | F42: 8.14 | G42: -3.5 | H42: -3.55 | I42: 9.42 | J42: -5.23 | L42: -5.33 | M42: -6.77 | N42: -6.57 | O42: 4.88 | Q42: 3.14 | R42: 2.57 | S42: 2.55 | T42: 2.59 | U42: 2.52 | V42: 3.38 | W42: 3.08 | Z42: -4.84 | AA42: -7.4 | AB42: -5.63 | AC42: -5.25 | AD42: -6.18 | AE42: 13.69 | AF42: 17.74 | AH42: 5.2 | AI42: -4.43 | AJ42: -4.42 | AK42: -4.75 | AL42: 10.16
C43: 8.05 | D43: 11.24 | E43: 10.59 | F43: 7.92 | G43: -3.75 | H43: -3.7 | I43: -3.75 | J43: 10.59 | L43: 1.83 | M43: 2.39 | N43: 2.23 | O43: 2.25 | Q43: -3.73 | R43: -3.69 | S43: 5.02 | T43: 5.06 | U43: 5.18 | V43: 5.2 | W43: -4.69 | Z43: 0.67 | AA43: 0.68 | AB43: 0.74 | AC43: 0.83 | AD43: 0.78 | AE43: 0.79 | AF43: 0.98 | AH43: 3.92 | AI43: -5.33 | AJ43: -4.9 | AK43: -4.45 | AL43: 4.9
C44: -3.52 | D44: 6.64 | E44: -4.38 | F44: 6.48 | G44: -3.57 | H44: -3.64 | I44: -3.58 | J44: -4.38 | L44: -4.78 | M44: 8.16 | N44: 8.84 | O44: -3.65 | Q44: 5.26 | R44: 5.76 | S44: 5.61 | T44: -4 | U44: 5.58 | V44: 6.28 | W44: -4.41 | Z44: -4.35 | AA44: -4.02 | AB44: -5.39 | AC44: -3.74 | AD44: -4.05 | AE44: -5.4 | AF44: -6.54 | AH44: 1.71 | AI44: 1.65 | AJ44: 1.81 | AK44: -4.44 | AL44: 1.53
C45: -4.68 | D45: -4.29 | E45: -4.98 | F45: -4.86 | G45: -3.69 | H45: -4.39 | I45: -4.84 | J45: -4.98 | L45: 2.03 | M45: 2.19 | N45: 2.39 | O45: 2.19 | Q45: -4.19 | R45: -3.73 | S45: -3.54 | T45: -3.7 | U45: -3.48 | V45: -3.58 | W45: -4.24 | Z45: 5.55 | AA45: 10.43 | AB45: 7.75 | AC45: 4.94 | AD45: 5.57 | AE45: 5.31 | AF45: 8.27 | AH45: -8.72 | AI45: -6.08 | AJ45: -5.49 | AK45: -5.37 | AL45: -7.48
C46: 6.43 | D46: 7.51 | E46: 9.05 | F46: 6.82 | G46: 5.66 | H46: 6.39 | I46: 6.17 | J46: 9.05 | L46: -4.25 | M46: -4.77 | N46: -4.88 | O46: -3.81 | Q46: -4.98 | R46: -4.27 | S46: -3.98 | T46: 10.26 | U46: -3.65 | V46: -3.67 | W46: -6 | Z46: 2.51 | AA46: 3.07 | AB46: 2.94 | AC46: 2.51 | AD46: 2.6 | AE46: 2.71 | AF46: 2.4 | AH46: -7.43 | AI46: -5.53 | AJ46: -4.65 | AK46: -4.36 | AL46: -6.82
C47: 6.7 | D47: -4.28 | E47: -3.63 | F47: -3.55 | G47: -3.38 | H47: 6.76 | I47: 7.42 | J47: -3.63 | L47: -5.54 | M47: 20.89 | N47: 23.81 | O47: 2.32 | Q47: 8.72 | R47: -5.35 | S47: -4.98 | T47: -5.25 | U47: -4.79 | V47: -6.05 | W47: -4.37 | Z47: -5.06 | AA47: 3.14 | AB47: 2.66 | AC47: 2.75 | AD47: -4.8 | AE47: -4.34 | AF47: -5.32 | AH47: -6.49 | AI47: 15.46 | AJ47: -5.25 | AK47: -5.19 | AL47: -4.18
L48: -4.89 | M48: 7.94 | N48: -4.65 | O48: -5.39 | Z48: 3.18 | AA48: 4.2 | AB48: -4.34 | AC48: 3.35 | AD48: 3.22 | AE48: -3.97 | AF48: -6.72 | AH48: -3.96 | AI48: -5.19 | AJ48: -4.44 | AK48: -4.54 | AL48: 8.14
L49: -6.86 | M49: -7.74 | N49: -8.66 | O49: -4.23 | Z49: -6.98 | AA49: -8.47 | AB49: -8.71 | AC49: -6.48 | AD49: -7.42 | AE49: -6.5 | AF49: -7.74 | AH49: 5.89 | AI49: -4.08 | AJ49: 3.37 | AK49: -4.58 | AL49: 4.04
L50: 15.18 | M50: 17.39 | N50: 16.71 | O50: -6.63 | Z50: 4.94 | AA50: 5.45 | AB50: 5.13 | AC50: 4.29 | AD50: 4.33 | AE50: 5.64 | AF50: 6.05
L51: -4.52 | M51: 11.12 | N51: -4.81 | O51: -5.07 | Z51: 4.18 | AA51: 4.9 | AB51: 4.89 | AC51: 4.65 | AD51: 4.06 | AE51: 4.44 | AF51: 6.06
Z52: 1.67 | AA52: 2.2 | AB52: 2.38 | AC52: -4.88 | AD52: -5.65 | AE52: 2.29 | AF52: 2.88
...

Sheet Modelo semana 25
A1: Tabla. Modelo seleccionado por pais segun ≠ metricas combinadas
B2: roi_last_25_matches_sb_sin_ea | C2: roi_last_25_matches_sb_con_ea | D2: roi_last_25_matches_sin_ea | E2: roi_last_25_matches_con_ea | F2: ROI_sb_sin_ea | G2: ROI_sin_ea | H2: ROI_sb_con_ea | I2: ROI_con_ea | K2: ['ROI_sin_ea', 'ROI_con_ea'] | L2: ['ROI_sb_sin_ea', 'ROI_sb_con_ea'] | M2: ['ROI_sb_sin_ea', 'ROI_sin_ea', 'ROI_sb_con_ea', 'ROI_con_ea'] | N2: ['roi_last_25_matches_sb_sin_ea', 'ROI_sin_ea', 'roi_last_25_matches_sb_con_ea', 'ROI_con_ea'] | O2: ['roi_last_25_matches_sin_ea', 'ROI_sin_ea', 'roi_last_25_matches_con_ea', 'ROI_con_ea'] | P2: ['ROI_sb_sin_ea', 'ROI_sb_con_ea', 'roi_last_25_matches_sb_sin_ea', 'roi_last_25_matches_sb_con_ea']
A3: ENG | B3: 343 | C3: 343 | D3: 343 | E3: 343 | F3: 395 | G3: 395 | H3: 395 | I3: 395 | K3: 395 | L3: 395 | M3: 395 | N3: 343 | O3: 343 | P3: 343
A4: FRA | B4: 1127 | C4: 724 | D4: 724 | E4: 724 | F4: 724 | G4: 724 | H4: 724 | I4: 724 | K4: 724 | L4: 724 | M4: 724 | N4: 724 | O4: 724 | P4: 724
A5: GER | B5: 1051 | C5: 1051 | D5: 1051 | E5: 1051 | F5: 1051 | G5: 1051 | H5: 1051 | I5: 1051 | K5: 1051 | L5: 1051 | M5: 1051 | N5: 1051 | O5: 1051 | P5: 1051
A6: ITA | B6: 622 | C6: 622 | D6: 47 | E6: 47 | F6: 19 | G6: 19 | H6: 1623 | I6: 1623 | K6: 1623 | L6: 1623 | M6: 1623 | N6: 47 | O6: 47 | P6: 47
A7: SPA | B7: 1447 | C7: 1606 | D7: 1447 | E7: 1545 | F7: 1051 | G7: 1051 | H7: 112 | I7: 112 | K7: 112 | L7: 112 | M7: 112 | N7: 1606 | O7: 1243 | P7: 1606
E10: Hasta el sabado incluido
E11: england | F11: 343
E12: france | F12: 724
E13: germany | F13: 1051
E14: italy | F14: 47
E15: spain | F15: 1447
E18: En el iniicio del domingo:
E19: england | F19: 663
E20: france | F20: 654
E21: germany | F21: 1051
E22: italy | F22: 622
E23: spain | F23: 1545
C32: id_country | D32: country | E32: iteration_date | F32: n_model | G32: model_name | H32: ROI_sin_ea | I32: m_home | J32: m_draw | K32: m_away | L32: Average m | M32: m_to_use | N32: ROI_con_ea | O32: Multiplicador ea
C33: 6 | D33: argentina | E33: 45685 | F33: 616 | G33: LogisticRegression | H33: =5.8410821479406*100 -> 584.10821 | I33: 70 | J33: 45 | K33: 10 | N33: 31833.094 | O33: =N33/H33 -> 54.498624
C34: 167 | D34: usa
C35: 48 | D35: england | E35: 45679 | F35: 343 | G35: LogisticRegression | H35: =1.95083127981317*100 -> 195.08313 | I35: 10 | J35: 25 | K35: 25 | L35: =AVERAGE(I35:K35) -> 20 | M35: =L35*'Data preparation'!$C$2 -> 2 | N35: 2031.7274 | O35: =N35/H35 -> 10.414675
C36: 55 | D36: france | E36: 45679 | F36: 724 | G36: LogisticRegression | H36: =3.44623889518345*100 -> 344.62389 | I36: 70 | J36: 45 | K36: 45 | L36: =AVERAGE(I36:K36) -> 53.333333 | M36: =L36*'Data preparation'!$C$2 -> 5.3333333 | N36: 7144.8114 | O36: =N36/H36 -> 20.7322
C37: 59 | D37: germany | E37: 45680 | F37: 1051 | G37: LogisticRegression | H37: =5.03501136998037*100 -> 503.50114 | I37: 70 | J37: 70 | K37: 10 | L37: =AVERAGE(I37:K37) -> 50 | M37: =L37*'Data preparation'!$C$2 -> 5 | N37: 73522.012 | O37: =N37/H37 -> 146.02154
C38: 77 | D38: italy | E38: 45677 | F38: 281 | G38: LogisticRegression | H38: =2.76792853614368*100 -> 276.79285 | I38: 10 | J38: 70 | K38: 70 | L38: =AVERAGE(I38:K38) -> 50 | M38: =L38*'Data preparation'!$C$2 -> 5 | N38: 13938.355 | O38: =N38/H38 -> 50.35663
C39: 148 | D39: spain | E39: 45677 | F39: 1051 | G39: LogisticRegression | H39: =4.33116583093229*100 -> 433.11658 | I39: 45 | J39: 10 | K39: 25 | L39: =AVERAGE(I39:K39) -> 26.666667 | M39: =L39*'Data preparation'!$C$2 -> 2.6666667 | N39: 5748.9466 | O39: =N39/H39 -> 13.273439

Sheet Modelo semana 26
A2: 1681 | B2: 0.07 | D2: 0.74 | G2: 1681 | K2: 0.13 | L2: 0.78
A3: 683 | B3: 0.12 | D3: 0.93 | G3: 683 | K3: 0.13 | L3: 0.91
A4: 354 | B4: 0.01 | D4: 0.76 | G4: 354 | K4: 0.09 | L4: 0.85
A5: 1023 | B5: 0.24 | D5: 0.94 | G5: 1023 | K5: 0.22 | L5: 0.91
A6: 508 | B6: 0.38 | D6: 1 | G6: 508 | K6: 0.45 | L6: 1
B9: Bank inicial part 100 | C9: Bank final con assess | D9: ROI assess
A10: 1681 | B10: 410 | C10: 342 | D10: =(C10-B10)/B10 -> -0.16585366 | F10: Tal vez seleccionar por last 50 nada mas? hubiera seleccionado mejores modelos?
A11: 683 | B11: 440 | C11: 374 | D11: =(C11-B11)/B11 -> -0.15 | F11: Usar f1_score en vez de accuracy.
A12: 354 | B12: 585 | C12: 447 | D12: =(C12-B12)/B12 -> -0.23589744
A13: 1023 | D13: =(C13-B13)/B13 -> #DIV/0!
A14: 508 | D14: =(C14-B14)/B14 -> #DIV/0!
H16: Es evidente que la seleccion actual no funciona porque seleccionaba totalmente otros modelos y los modelos que mejor rindieron no estaban ni cerca de ser elegidos.
H17: Mejor modelo --> Modelo a seleccionar cuando tenia test... ver con que metricas los hubiera seleccionado.. | I17: metodo de seleccion
A18: 332 | B18: 0.05 | C18: 0.85 | G18: ENG | H18: 332 | I18: Por f1_score en last 50 no. Por expected ROI no.
A19: 518 | B19: 0.01 | C19: 0.81 | G19: FRA | H19: 1,288 1,117 1,126 | I19: Por recall / f1_score en last 50, en FRA quedaban cerca de elegir los mejores modelos... si lo mezclaba con f1_score en last_25 quedaban. Pero no usar ROI ni test_acc. Expecetd no (aunque mejor que recall y esas)
A20: 1082 | B20: 0.04 | C20: 0.89 | G20: GER | H20: 411 | I20: Por recall. No last matches. Por expected ROI? Hubiera seleccionado el 411.
G21: ITA | H21: 1,216 1,016 1,015 1,270 | I21: Por recall en last 50. Luego por f1_score en last 50 si. Por ROI no. En last 25 no tnato. Expected ROI mejor que recall y esas. Incluso seleccionaba el 1216.
G22: SPA | H22: 530 1,151 770 508 1,201 | I22: Por recall? Por expected ROI? Por expecetd ROI, seleccionaba el 770 y 3ro 1201
I24: CONCLUSIONES
B25: country | I25: El expected estaria bueno pero funciona mal en ENG?
B26: england | C26: 332
B27: france | C27: 1288
B28: germany | C28: 411
B29: italy | C29: 1015
B30: spain | C30: 530 | I30: PLAN DE ACCION:
I31: Seleccion de modelos candidatos
I32: el 411 de GER casi queda fuera del recorte de candidatos. Dado que el ROI no sirve, usar solo f1_score?
I33: En FRA, sucedia lo mismo, los mejores modelos casi quedan fuera del corte por candidatos.
I35: No considero el expected roi tampoco. Funciona muy mal para algunos paises.
I39: Metricas para selec modelo.
I40: Usar expected en ligas donde la correalcion entre ROI y expected roi sea alto? No al reves...
I41: Usar recall o f1_score? Con recall, funciona joya salvo en FRA.
I42: Cuando considero recall en last_50 y recall_en last_25 --> Funciona muchisimo mejor.
I44: Uso las mismas metricas para seleccionar los candidatos. Simplifico y ademas genero consistencia.

Sheet Modelo semana 27
B1: Cambio en seleccion: tener en cuenta ROI_sin_ea para seleccionar modelos. O sea, en la seleccion de candidatos recall y roi_sin_ea y en la seleccion del modelo recall y roi_sin_ea en ultimos partidos.
C3: antes | D3: despues | H3: antes: seleccionando modelos por recall.
B4: ENG | C4: ROI | D4: ROI | H4: despues: seleccionando modelos por recall y roi_sin_ea
B5: Sum | C5: =SUM(C6:C18) -> 23.59 | D5: =SUM(D6:D18) -> 33.21 | E5: =(D5-C5)/C5 -> 0.40779992 | F5: Mejora!
C6: 2.99 | D6: 4.4
C7: 3.75 | D7: 3.06 | H7: En ENG, - el 2278 no habia quedado entre los mejores modelos por recall. - los mejores modelos crecen en ROI_sin_ea. Es bueno
C8: 3.6 | D8: 2.27
C9: 1.86 | D9: 2.3 | H9: En FRA, - el 518 no habia quedado entre los mejores modelos por recall.
C10: 1.49 | D10: 1.89
C11: 0.3 | D11: 4.18 | H11: En GER, - el 645 no habia quedado entre los mejores modelos por recall.
C12: 1.11 | D12: 3.1
C13: 2.12 | D13: 2.35 | H13: En ITA, - el 1023 si era seleccionado por recall.
C14: 2.27 | D14: 1.89
C15: 1.29 | D15: 1.84
C16: 0.73 | D16: 1.37 | H16: En SPA, - el 499 no habia quedado entre los mejores modelos por recall.
C17: 1.01 | D17: 2.3
C18: 1.07 | D18: 2.26
B20: FRA | C20: antes | D20: despues
B21: Sum | C21: =sum(C22:C34) -> 17.92 | D21: =sum(D22:D34) -> 25.11 | E21: =(D21-C21)/C21 -> 0.40122768 | F21: Mejora!
C22: 1.97 | D22: 3.42
C23: 1.37 | D23: 2.97
C24: 0.9 | D24: 1.97
C25: 1.11 | D25: 1.29
C26: 1.42 | D26: 1.68
C27: 1.63 | D27: 1.37
C28: 2.46 | D28: 2.09
C29: 2.77 | D29: 1.34
C30: 1.67 | D30: 3.31
C31: 0.3 | D31: 1.58
C32: 1.63 | D32: 0.92
C33: 0.09 | D33: 0.91
C34: 0.6 | D34: 2.26
B37: GER | C37: antes | D37: despues
B38: Sum | C38: =sum(C39:C51) -> 41.51 | D38: =sum(D39:D51) -> 42.82 | E38: =(D38-C38)/C38 -> 0.031558661 | F38: Mantiene
C39: 1.76 | D39: 3.01
C40: 5.05 | D40: 5.05
C41: 3.96 | D41: 3.16
C42: 3.42 | D42: 2.13
C43: 4.29 | D43: 3.96
C44: 4.28 | D44: 2.16
...

Sheet Data preparation
B2: porc_m | C2: 0.1
B3: average m_to_use | C3: =AVERAGE(#REF!) -> #REF!
AE4: Correl | AF4: =CORREL(AE6:AE10000,AF6:AF10000) -> 0.41131828
B5: Promedio | L5: PROMEDIO PONDERADO | P5: CONTADOR DE RDOS | AE5: x | AF5: y
B6: Promedio ROI pp top 10 modelos | F6: Promedio ROI pp top 20 modelos | L6: Mean variable | N6: Mean Weigh variable | P6: Result | R6: Count result | V6: Comparo con result real | AA6: Shape | AB6: X | AE6: 519.2 | AF6: -50.86
L7: =AVERAGE(L10:L19) -> #VALUE! | N7: =SUM(N10:N29)/SUM(M10:M19) -> #VALUE! | P7: 1 | R7: 1 | S7: =COUNTIF($P$7:$P1775,R7) -> 51 | T7: =S7/$S$10 -> 0.46363636 | V7: 33 | W7: =(S7-V7)/V7 -> 0.54545455 | AA7: (81, 8) | AB7: =LEFT(REPLACE(AA7,1,1,""),FIND(",", AA7)-2)/1 -> 81 | AE7: 415.94 | AF7: -60.55
B8: 3.60 | C8: =REPLACE(B8,FIND(".",B8),1,",")*1 -> #VALUE! | F8: 5.80 | G8: =REPLACE(F8,FIND(".",F8),1,",")*1 -> #VALUE! | I8: 30 | J8: 50 | P8: 2 | R8: 0 | S8: =COUNTIF($P$7:$P1776,R8) -> 29 | T8: =S8/$S$10 -> 0.26363636 | V8: 19 | W8: =(S8-V8)/V8 -> 0.52631579 | AA8: (54, 27) | AB8: =LEFT(REPLACE(AA8,1,1,""),FIND(",", AA8)-2)/1 -> 54 | AE8: 396.62 | AF8: 77.53
B9: 3.67 | C9: =REPLACE(B9,FIND(".",B9),1,",")*1 -> #VALUE! | F9: 4.92 | G9: =REPLACE(F9,FIND(".",F9),1,",")*1 -> #VALUE! | I9: 30 | J9: 50 | L9: Variable | M9: Peso | N9: Variable * Peso | P9: 1 | R9: 2 | S9: =COUNTIF($P$7:$P1777,R9) -> 30 | T9: =S9/$S$10 -> 0.27272727 | V9: 24 | W9: =(S9-V9)/V9 -> 0.25 | AA9: (81, 23) | AB9: =LEFT(REPLACE(AA9,1,1,""),FIND(",", AA9)-2)/1 -> 81 | AE9: 386.95 | AF9: 196.62
B10: 3.51 | C10: =REPLACE(B10,FIND(".",B10),1,",")*1 -> #VALUE! | F10: 9.15 | G10: =REPLACE(F10,FIND(".",F10),1,",")*1 -> #VALUE! | I10: 20 | J10: 40 | L10: =C8 -> #VALUE! | M10: =M11*2 -> 512 | N10: =M10*L10 -> #VALUE! | P10: 0 | S10: =SUM(S7:S9) -> 110 | V10: =SUM(V7:V9) -> 76 | AA10: (54, 54) | AB10: =LEFT(REPLACE(AA10,1,1,""),FIND(",", AA10)-2)/1 -> 54 | AE10: 325.02 | AF10: 159.3
B11: 2.74 | C11: =REPLACE(B11,FIND(".",B11),1,",")*1 -> #VALUE! | F11: 3.83 | G11: =REPLACE(F11,FIND(".",F11),1,",")*1 -> #VALUE! | I11: 20 | J11: 40 | L11: =C9 -> #VALUE! | M11: =M12*2 -> 256 | N11: =M11*L11 -> #VALUE! | P11: 2 | AA11: (54, 24) | AB11: =LEFT(REPLACE(AA11,1,1,""),FIND(",", AA11)-2)/1 -> 54 | AE11: 311 | AF11: 139.56
B12: 3.65 | C12: =REPLACE(B12,FIND(".",B12),1,",")*1 -> #VALUE! | F12: 5.94 | G12: =REPLACE(F12,FIND(".",F12),1,",")*1 -> #VALUE! | I12: 20 | J12: 40 | L12: =C10 -> #VALUE! | M12: =M13*2 -> 128 | N12: =M12*L12 -> #VALUE! | P12: 1 | AA12: (54, 54) | AB12: =LEFT(REPLACE(AA12,1,1,""),FIND(",", AA12)-2)/1 -> 54 | AE12: 298.88 | AF12: 9.97
B13: 3.63 | C13: =REPLACE(B13,FIND(".",B13),1,",")*1 -> #VALUE! | F13: 6.18 | G13: =REPLACE(F13,FIND(".",F13),1,",")*1 -> #VALUE! | I13: 20 | J13: 40 | L13: =C11 -> #VALUE! | M13: =M14*2 -> 64 | N13: =M13*L13 -> #VALUE! | P13: 1 | S13: Tipto | T13: BET | U13: FB | AA13: (81, 4) | AB13: =LEFT(REPLACE(AA13,1,1,""),FIND(",", AA13)-2)/1 -> 81 | AE13: 278.86 | AF13: -2.22
B14: 3.68 | C14: =REPLACE(B14,FIND(".",B14),1,",")*1 -> #VALUE! | F14: 9.33 | G14: =REPLACE(F14,FIND(".",F14),1,",")*1 -> #VALUE! | I14: 20 | J14: 40 | L14: =C12 -> #VALUE! | M14: =M15*2 -> 32 | N14: =M14*L14 -> #VALUE! | P14: 1 | R14: 1 | S14: 18 | T14: 21 | U14: 11 | AA14: (81, 15) | AB14: =LEFT(REPLACE(AA14,1,1,""),FIND(",", AA14)-2)/1 -> 81 | AE14: 248.07 | AF14: -78.26
B15: 3.64 | C15: =REPLACE(B15,FIND(".",B15),1,",")*1 -> #VALUE! | F15: 8.30 | G15: =REPLACE(F15,FIND(".",F15),1,",")*1 -> #VALUE! | I15: 20 | J15: 40 | L15: =C13 -> #VALUE! | M15: =M16*2 -> 16 | N15: =M15*L15 -> #VALUE! | P15: 1 | R15: 0 | S15: 8 | T15: 0 | U15: 13 | AA15: (54, 20) | AB15: =LEFT(REPLACE(AA15,1,1,""),FIND(",", AA15)-2)/1 -> 54 | AE15: 247.8 | AF15: -49.83
B16: 2.71 | C16: =REPLACE(B16,FIND(".",B16),1,",")*1 -> #VALUE! | F16: 5.73 | G16: =REPLACE(F16,FIND(".",F16),1,",")*1 -> #VALUE! | I16: 20 | J16: 40 | L16: =C14 -> #VALUE! | M16: =M17*2 -> 8 | N16: =M16*L16 -> #VALUE! | P16: 0 | R16: 2 | S16: 10 | T16: 15 | U16: 12 | AA16: (81, 10) | AB16: =LEFT(REPLACE(AA16,1,1,""),FIND(",", AA16)-2)/1 -> 81 | AE16: 245.03 | AF16: 213.08
B17: 2.80 | C17: =REPLACE(B17,FIND(".",B17),1,",")*1 -> #VALUE! | F17: 5.42 | G17: =REPLACE(F17,FIND(".",F17),1,",")*1 -> #VALUE! | I17: 20 | J17: 40 | L17: =C15 -> #VALUE! | M17: =M18*2 -> 4 | N17: =M17*L17 -> #VALUE! | P17: 1 | R17: Total | S17: =SUM(S14:S16) -> 36 | T17: =SUM(T14:T16) -> 36 | U17: =SUM(U14:U16) -> 36 | AE17: 215.88 | AF17: 45.87
F18: 7.91 | G18: =REPLACE(F18,FIND(".",F18),1,",")*1 -> #VALUE! | I18: 10 | L18: =C16 -> #VALUE! | M18: =M19*2 -> 2 | N18: =M18*L18 -> #VALUE! | P18: 1 | AE18: 189.05 | AF18: 51.45
B19: Average | C19: =AVERAGE(C8:C17) -> #VALUE! | F19: 7.85 | G19: =REPLACE(F19,FIND(".",F19),1,",")*1 -> #VALUE! | I19: 10 | L19: =C17 -> #VALUE! | M19: 1 | N19: =M19*L19 -> #VALUE! | P19: 1 | AA19: Prom | AB19: =AVERAGE(AB7:AB16) -> 67.5 | AE19: 161.12 | AF19: 125.27
F20: 4.24 | G20: =REPLACE(F20,FIND(".",F20),1,",")*1 -> #VALUE! | I20: 10 | P20: 1 | AE20: 147.56 | AF20: -64.93
F21: 4.73 | G21: =REPLACE(F21,FIND(".",F21),1,",")*1 -> #VALUE! | I21: 10 | P21: 1 | S21: Tipto | T21: BET | U21: FB | AE21: 146.62 | AF21: 74.55
F22: 5.56 | G22: =REPLACE(F22,FIND(".",F22),1,",")*1 -> #VALUE! | I22: 10 | P22: 0 | R22: 1 | S22: =S14/S$17 -> 0.5 | T22: =T14/T$17 -> 0.58333333 | U22: =U14/U$17 -> 0.30555556 | AE22: 143.08 | AF22: 57.92
F23: 45356 | G23: =REPLACE(F23,FIND(".",F23),1,",")*1 -> #VALUE! | I23: 10 | P23: 1 | R23: 0 | S23: =S15/S$17 -> 0.22222222 | T23: =T15/T$17 -> 0 | U23: =U15/U$17 -> 0.36111111 | AE23: 135.11 | AF23: -1.76
F24: 4.19 | G24: =REPLACE(F24,FIND(".",F24),1,",")*1 -> #VALUE! | I24: 10 | P24: 1 | R24: 2 | S24: =S16/S$17 -> 0.27777778 | T24: =T16/T$17 -> 0.41666667 | U24: =U16/U$17 -> 0.33333333 | AE24: 132.91 | AF24: 294.68
F25: 2.63 | G25: =REPLACE(F25,FIND(".",F25),1,",")*1 -> #VALUE! | I25: 10 | P25: 1 | R25: Total | S25: =SUM(S22:S24) -> 1 | T25: =SUM(T22:T24) -> 1 | U25: =SUM(U22:U24) -> 1 | AE25: 127.74 | AF25: 332.05
F26: 4.54 | G26: =REPLACE(F26,FIND(".",F26),1,",")*1 -> #VALUE! | I26: 10 | P26: 1 | AE26: 124.15 | AF26: 249.31
F27: 45542 | G27: =REPLACE(F27,FIND(".",F27),1,",")*1 -> #VALUE! | I27: 10 | P27: 1 | AE27: 111.37 | AF27: 140.53
P28: 1 | AA28: n_iteration | AB28: roi | AC28: roi | AE28: 106.73 | AF28: -68.34
F29: Average | G29: =AVERAGE(G8:G27) -> #VALUE! | I29: =AVERAGE(I8:I27) -> 16 | J29: =AVERAGE(J8:J17) -> 42 | P29: 0 | AA29: 1051 | AB29: 207.56 | AC29: =VLOOKUP(AA29,$AA$48:$AB$62,2,0) -> 263.81 | AD29: =(AC29-AB29)/AB29 -> 0.27100597 | AE29: 101.39 | AF29: 207.24
P30: 0 | AA30: 112 | AB30: 185.35 | AC30: =VLOOKUP(AA30,$AA$48:$AB$62,2,0) -> 130.76 | AD30: =(AC30-AB30)/AB30 -> -0.29452387 | AE30: 95.51 | AF30: 214.38
P31: 2 | S31: prob_result_to_bet | T31: prob_bm | U31: odd | V31: kelly_crit | AA31: 752 | AB31: 121.6 | AC31: =VLOOKUP(AA31,$AA$48:$AB$62,2,0) -> 78.68 | AD31: =(AC31-AB31)/AB31 -> -0.35296053 | AE31: 93.4 | AF31: 111.66
B32: Falta entrenarlos: 1) sin rellenar formaciones antes de construir 2) Con todos l_models y no solo logistic. | P32: 0 | S32: 40 | T32: 50 | AA32: 1475 | AB32: 120.82 | AC32: =VLOOKUP(AA32,$AA$48:$AB$62,2,0) -> 83.5 | AD32: =(AC32-AB32)/AB32 -> -0.30888926 | AE32: 90.38 | AF32: -64.77
B33: 3) Integracion por liga. --> FRA tenes que recolectar Sofifa de la Ligue 2 del fifa 25 antes... | P33: 1 | S33: 80 | T33: 90 | AA33: 1545 | AB33: 111.42 | AC33: =VLOOKUP(AA33,$AA$48:$AB$62,2,0) -> 101.16 | AD33: =(AC33-AB33)/AB33 -> -0.092084006 | AE33: 86.8 | AF33: 86.2
P34: 0 | AA34: 814 | AB34: 104.32 | AC34: =VLOOKUP(AA34,$AA$48:$AB$62,2,0) -> 60.31 | AD34: =(AC34-AB34)/AB34 -> -0.421875 | AE34: 84.15 | AF34: 5.62
H35: Stake promedio | P35: 1 | AA35: 1426 | AB35: 101.23 | AC35: =VLOOKUP(AA35,$AA$48:$AB$62,2,0) -> 68.02 | AD35: =(AC35-AB35)/AB35 -> -0.3280648 | AE35: 83.01 | AF35: 43.27
G36: ENG | H36: 4.555 | P36: 1 | AA36: 1447 | AB36: 97.89 | AC36: =VLOOKUP(AA36,$AA$48:$AB$62,2,0) -> 138.76 | AD36: =(AC36-AB36)/AB36 -> 0.41750945 | AE36: 80.91 | AF36: 128.36
D37: =AVERAGE(D39:D1775) -> 4.8911538 | G37: FRA | H37: 7.5552941 | P37: 1 | AA37: 136 | AB37: 87.93 | AC37: =VLOOKUP(AA37,$AA$48:$AB$62,2,0) -> 58.8 | AD37: =(AC37-AB37)/AB37 -> -0.33128625 | AE37: 80.19 | AF37: -56.27
G38: GER | H38: 2.21 | P38: 2 | AA38: 1526 | AB38: 85.82 | AC38: =VLOOKUP(AA38,$AA$48:$AB$62,2,0) -> 53.3 | AD38: =(AC38-AB38)/AB38 -> -0.37893265 | AE38: 79.61 | AF38: -61.31
D39: 8.46 | G39: ITA | H39: 9.9382353 | P39: 1 | AA39: 952 | AB39: 78.09 | AC39: =VLOOKUP(AA39,$AA$48:$AB$62,2,0) -> 73.76 | AD39: =(AC39-AB39)/AB39 -> -0.055448841 | AE39: 78.89 | AF39: -18.54
D40: 7.25 | G40: SPA | H40: 3.3411111 | P40: 2 | AA40: 1606 | AB40: 77.21 | AC40: =VLOOKUP(AA40,$AA$48:$AB$62,2,0) -> 75.05 | AD40: =(AC40-AB40)/AB40 -> -0.027975651 | AE40: 78.73 | AF40: 134.76
D41: 7.15 | P41: 0 | AA41: 1164 | AB41: 76.05 | AC41: =VLOOKUP(AA41,$AA$48:$AB$62,2,0) -> 26.27 | AD41: =(AC41-AB41)/AB41 -> -0.65456936 | AE41: 78.25 | AF41: -66.82
...

Sheet Framework
B1: RENTABILIDAD | G1: DISTRIBUCION BETS
A2: n_model | B2: roi_50 | C2: roi_100 | D2: roi | E2: roi_por_partido | F2: % ROI 100 | G2: 1 | H2: X | I2: 2 | J2: # aciertos | K2: % aciertos | L2: # aciertos empate | M2: % aciertos empate | N2: Descarte x | O2: Orden de prioridad | P2: Obs | S2: SEMANA 29
F3: =IFERROR((E3-C3)/abs(C3),"") | K3: =IF(ISNUMBER(J3),J3/$E$29,"") | M3: =IF(ISNUMBER(L3),L3/H3,"")
F4: =IFERROR((E4-C4)/abs(C4),"") | K4: =IF(ISNUMBER(J4),J4/$E$29,"") | M4: =IF(ISNUMBER(L4),L4/H4,"") | S4: Volver a implementar ea por rdo para evitar esas caidas rancias en 1 de ITA y ENG. (en vez de doble oportunidad)
F5: =IFERROR((E5-C5)/abs(C5),"") | K5: =IF(ISNUMBER(J5),J5/$E$29,"") | M5: =IF(ISNUMBER(L5),L5/H5,"") | T5: Baja el m de SPA en relacion al resto, eso esta buenisimo.
F6: =IFERROR((E6-C6)/abs(C6),"") | K6: =IF(ISNUMBER(J6),J6/$E$29,"") | M6: =IF(ISNUMBER(L6),L6/H6,"") | T6: Me hubiera ido mucho mejor en esta semana 29. Cuanto mejor? | AD6: Eliminar x distrib? Si eliminara por distrib no elegigiria nunca el 145 en ENG
F7: =IFERROR((E7-C7)/abs(C7),"") | K7: =IF(ISNUMBER(J7),J7/$E$29,"") | M7: =IF(ISNUMBER(L7),L7/H7,"") | AD7: Si tengo en cuenta el ROI con ea en la seleccion con ea por rdo?
F8: =IFERROR((E8-C8)/abs(C8),"") | K8: =IF(ISNUMBER(J8),J8/$E$29,"") | M8: =IF(ISNUMBER(L8),L8/H8,"") | S8: definir dp primero por rdo y luego para auqellos en los que no funciono, usar un mismo m? | AD8: Kelly criterion con -0.5 x ej? para evitar realmente donde no conviene? No, no me siento comodo con eso.
F9: =IFERROR((E9-C9)/abs(C9),"") | K9: =IF(ISNUMBER(J9),J9/$E$29,"") | M9: =IF(ISNUMBER(L9),L9/H9,"")
F10: =IFERROR((E10-C10)/abs(C10),"") | K10: =IF(ISNUMBER(J10),J10/$E$29,"") | M10: =IF(ISNUMBER(L10),L10/H10,"")
F11: =IFERROR((E11-C11)/abs(C11),"") | K11: =IF(ISNUMBER(J11),J11/$E$29,"") | M11: =IF(ISNUMBER(L11),L11/H11,"")
F12: =IFERROR((E12-C12)/abs(C12),"") | K12: =IF(ISNUMBER(J12),J12/$E$29,"") | M12: =IF(ISNUMBER(L12),L12/H12,"")
F13: =IFERROR((E13-C13)/abs(C13),"") | K13: =IF(ISNUMBER(J13),J13/$E$29,"") | M13: =IF(ISNUMBER(L13),L13/H13,"")
F14: =IFERROR((E14-C14)/abs(C14),"") | K14: =IF(ISNUMBER(J14),J14/$E$29,"") | M14: =IF(ISNUMBER(L14),L14/H14,"")
F15: =IFERROR((E15-C15)/abs(C15),"") | K15: =IF(ISNUMBER(J15),J15/$E$29,"") | M15: =IF(ISNUMBER(L15),L15/H15,"") | S15: Observaciones: - en eng ya ningun modelo candidato es rentable en los utimos partidos. Tal vez es momento de reentrenar con sofifa actualizado. - en FRA
F16: =IFERROR((E16-C16)/abs(C16),"") | K16: =IF(ISNUMBER(J16),J16/$E$29,"") | M16: =IF(ISNUMBER(L16),L16/H16,"")
F17: =IFERROR((E17-C17)/abs(C17),"") | K17: =IF(ISNUMBER(J17),J17/$E$29,"") | M17: =IF(ISNUMBER(L17),L17/H17,"")
F18: =IFERROR((E18-C18)/abs(C18),"") | K18: =IF(ISNUMBER(J18),J18/$E$29,"") | M18: =IF(ISNUMBER(L18),L18/H18,"")
F19: =IFERROR((E19-C19)/abs(C19),"") | K19: =IF(ISNUMBER(J19),J19/$E$29,"") | M19: =IF(ISNUMBER(L19),L19/H19,"") | S19: Tendre que crear columna kelly_criterion en database de VPS
F20: =IFERROR((E20-C20)/abs(C20),"") | K20: =IF(ISNUMBER(J20),J20/$E$29,"") | M20: =IF(ISNUMBER(L20),L20/H20,"")
F21: =IFERROR((E21-C21)/abs(C21),"") | K21: =IF(ISNUMBER(J21),J21/$E$29,"") | M21: =IF(ISNUMBER(L21),L21/H21,"")
F22: =IFERROR((E22-C22)/abs(C22),"") | K22: =IF(ISNUMBER(J22),J22/$E$29,"") | M22: =IF(ISNUMBER(L22),L22/H22,"")
A24: Prom | B24: =IFERROR(AVERAGE(B3:B22),"") | C24: =IFERROR(AVERAGE(C3:C22),"") | D24: =IFERROR(AVERAGE(D3:D22),"") | E24: =IFERROR(AVERAGE(E3:E22),"") | F24: =IFERROR(AVERAGE(F3:F22),"") | S24: england | T24: 145 | U24: 145
S25: france | T25: 1172 | U25: 518
S26: germany | T26: 411 | U26: 812
G27: DISTRIBUCION REALIDAD | S27: italy | T27: 1267 | U27: 1023
G28: 1 | H28: X | I28: 2 | S28: spain | T28: 770 | U28: 1263
D29: # partidos | E29: =J29 -> 146 | G29: 59 | H29: 33 | I29: 54 | J29: =SUM(G29:I29) -> 146 | L29: result | M29: result to bet | O29: 1 | P29: =COUNTIF($M$30:$M1001,O29) -> 54
G30: =G29/$J$29 -> 0.40410959 | H30: =H29/$J$29 -> 0.2260274 | I30: =I29/$J$29 -> 0.36986301 | L30: 0 | M30: 2 | O30: 0 | P30: =COUNTIF($M$30:$M1002,O30) -> 23
L31: 2 | M31: 2 | O31: 2 | P31: =COUNTIF($M$30:$M1003,O31) -> 69 | S31: SEMANA 30
L32: 2 | M32: 2
G33: DISTRIBUCION HISTORICA | L33: 2 | M33: 2 | T33: era ea con kelly | W33: Metricas: F1_score + ROI sin ea + ROI con ea (ea con linear pero max Ex roi)
G34: 1 | H34: X | I34: 2 | L34: 0 | M34: 0 | S34: england | T34: 1626 | U34: Balance entre roi y ex roi | W34: 5193
G35: 0.485 | H35: 0.285 | I35: 0.23 | L35: 2 | M35: 2 | S35: france | T35: 4176 | U35: Balance entre roi y ex roi | W35: 4863
G36: =ROUND(G35*$E$29,0) -> 71 | H36: =ROUND(H35*$E$29,0) -> 42 | I36: =ROUND(I35*$E$29,0) -> 34 | L36: 2 | M36: 2 | S36: germany | T36: 5130 | W36: 3032
L37: 2 | M37: 2 | S37: italy | T37: 2114 | W37: 2114
F38: DIF | G38: =G30-G35 -> -0.080890411 | H38: =H30-H35 -> -0.058972603 | I38: =I30-I35 -> 0.13986301 | L38: 1 | M38: 0 | S38: spain | W38: 240
L39: 1 | M39: 1
L40: 1 | M40: 1
L41: 1 | M41: 1
...

Sheet Reseña modelos
A1: ]
C2: Entrenamiento | F2: Produccion
B3: Modelo | C3: Rapidez en seleccion de hiperparametros | D3: Errores en entrenamiento | E3: ROI | F3: Sensibilidad a datos de entrada | G3: Distribucion de probas | H3: Balanceo de clases
B4: Logistic | C4: Alta | D4: Puede no converger pero ahi podes subir el max_iter | E4: Alto | F4: Muy poca | G4: Soft
B5: XGBClassifier | C5: Baja | E5: Alto | F5: Altisima | G5: A veces, deficiente
B6: Red neuronal propia | C6: Alta | D6: Consumo de memoria y corta entrenamiento | E6: Alto | F6: ?
B7: SVC | C7: Media a alta | E7: Bajo | F7: Nula? | H7: Con scoring accuracy, solo predice 2 clases de las 3. Recien con f1_score, empezó a predecir las 3 clases.
B8: MLPClassifier | C8: Muy baja | E8: Medio? | F8: Alta? | G8: Algunas muy chotas?
B9: GradientBoosting | C9: Muy baja
B10: RandomForestClassifier | G10: Soft
B11: DecisionTreeClassifier | G11: Depende de min_samples_leaf

Sheet Metricas semana 33
B1: ENG | P1: FRA | Y1: Tras el sabado | AE1: GER | AT1: ITA | BJ1: SPA | CE1: Corr error en test | CF1: test_acc | CG1: recall | CH1: f1_score | CI1: roi
B2: Max roi en prod | F2: Max roi all countries | G2: Max roi all countries | I2: Max roi all countries | J2: Max error en prod | N2: Independiente | P2: Max roi en prod | S2: Max error en prod | W2: Independiente | Y2: Max roi | Z2: Independiente | AA2: Max roi all countries | AE2: Max roi en prod | AH2: Max error en prod | AL2: Independiente | AO2: Independiente | AP2: Max roi all countries | AT2: Max roi en prod | AW2: Max error en prod | BB2: Independiente | BE2: Independiente | BJ2: Max roi en prod | BN2: Max error en prod | BT2: Independiente | BW2: Independiente | BX2: Max roi all countries | CE2: eng | CF2: -0.72106 | CG2: -0.55562 | CH2: -0.27038 | CI2: -0.63511
B3: 1 gral + 1 part | C3: f1_score + 1 part | D3: 3 + imp | E3: + impor sin mi bias | F3: + impor all countries sin corr | G3: + impor all countries sin corr sin_expected | H3: mis metricas | I3: + impor all countries sin corr sin expected salvo error | J3: Errores + gp mas impor | K3: Errores + gp mas impor | L3: Solo errores | M3: + imp con pesos ≠ | N3: Candidatos por roi | P3: 1 gral + 1 part | Q3: f1_score + 1 part | R3: 3 + imp | S3: Errores + gp mas impor | T3: Errores + gp mas impor | U3: Solo errores | V3: + imp con pesos ≠ | W3: Candidatos por roi | Y3: + impor sin mi bias | Z3: Candidatos por roi | AA3: + impor all countries sin corr | AB3: + impor all countries sin corr sin expected salvo error | AC3: "mis metricas" | AE3: 1 gral + 1 part | AF3: f1_score + 1 part | AG3: 3 + imp | AH3: Errores + gp mas impor | AI3: Errores + gp mas impor | AJ3: Solo errores | AK3: + imp con pesos ≠ | AL3: Candidatos por roi | AN3: + impor sin mi bias | AO3: Candidatos por roi | AP3: + impor all countries sin corr | AQ3: + impor all countries sin corr sin expected salvo error | AR3: "mis metricas" | AT3: 1 gral + 1 part | AU3: f1_score + 1 part | AV3: 3 + imp | AW3: Errores + gp mas impor | AX3: Errores + gp mas impor | AZ3: Solo errores | BA3: + imp con pesos ≠ | BB3: Candidatos por roi | BD3: + impor sin mi bias | BE3: Candidatos por roi | BF3: + impor all countries sin corr sin expected salvo error | BG3: "mis metricas" | BJ3: 1 gral + 1 part | BK3: f1_score + 1 part | BL3: 2 + imp | BM3: 3 + imp | BN3: Errores + gp mas impor | BO3: Errores + gp mas impor | BQ3: Solo errores | BR3: + imp con pesos ≠ | BS3: + imp con pesos ≠ MOD | BT3: Candidatos por roi | BV3: + impor sin mi bias | BW3: Candidatos por roi | BX3: + impor all countries sin corr | BY3: + impor all countries sin corr sin expected salvo error | BZ3: "mis metricas" | CE3: fra | CF3: -0.2884 | CG3: -0.16526 | CH3: 0.022587 | CI3: -0.20427
B4: error + gp_draw | C4: f1_score + gp_draw | D4: error + expected_roi + gp_draw | E4: expected_error': 0.66, 'error': 0.33 | F4: 0.47 expected_f1_score_away 0.29 f1_score_draw 0.24 expected_f1_score_home | G4: 0.51 f1_score_draw 0.37 accuracy_home 0.11 f1_score_away | H4: error + gp_away | I4: 0.4 f1_score_draw 0.3 expected_error 0.3 f1_score_away | J4: Expected_error + Error + gp_res | K4: Expected_error + Error + gp_res (≠ pesos) | L4: 0.7 Expected_error + 0.3 Error | M4: expected_error': 0.5, 'error': 0.25, 'gp_draw': 0.25 | N4: 0.4 Expected_error 0.4 error 0.2 gp_draw 0.2 gp_away | P4: error + gp_home | Q4: f1_score + gp_home | R4: gp_home accuracy_away error | S4: Expected_error + Error + gp_res | T4: Expected_error + Error + gp_res (≠ pesos) | U4: 0.7 Expected_error + 0.3 Error | V4: gp_home': 0.4, 'f1_score_draw': 0.4, 'error': 0.2 | W4: 0.4 Expected_error 0.4 error 0.2 gp_draw 0.2 gp_away | Y4: gp_home': 0.5, 'accuracy_away': 0.3, 'error': 0.2 | Z4: 0.4 Expected_error 0.4 error 0.2 gp_draw 0.2 gp_away | AA4: 0.47 expected_f1_score_away 0.29 f1_score_draw 0.24 expected_f1_score_home | AB4: 0.4 f1_score_draw 0.3 expected_error 0.3 f1_score_away | AC4: error + gp_away | AE4: f1_score + f1_score_draw | AF4: f1_score + f1_score_draw | AG4: f1_score_draw f1_score expected_f1_score_away | AH4: Expected_error + Error + gp_res | AI4: Expected_error + Error + gp_res (≠ pesos) | AJ4: 0 Expected_error + 1 Error | AK4: gp_away': 0.66, 'error': 0.33 | AL4: 0.4 Expected_error 0.4 error 0.2 gp_draw 0.2 gp_away | AN4: f1_score_draw': 0.45, 'expected_f1_score_draw': 0.35, 'expected_f1_score_home': 0.2 | AO4: 0.4 Expected_error 0.4 error 0.2 gp_draw 0.2 gp_away | AP4: 0.47 expected_f1_score_away 0.29 f1_score_draw 0.24 expected_f1_score_home | AQ4: 0.4 f1_score_draw 0.3 expected_error 0.3 f1_score_away | AR4: error + gp_away | AT4: roi + gp_home | AU4: f1_score + gp_home | AV4: f1_score_home roi expected_accuracy_away | AW4: Expected_error + Error + gp_res | AX4: Expected_error + Error + gp_res (≠ pesos) | AY4: Expected_error + Error + gp_away | AZ4: 0.3 Expected_error + 0.7 Error | BA4: gp_home': 0.5, 'error': 0.5 | BB4: 0.4 Expected_error 0.4 error 0.2 gp_draw 0.2 gp_away | BD4: gp_home': 0.5, 'recall': 0.3, 'roi': 0.2 | BE4: 0.4 Expected_error 0.4 error 0.2 gp_draw 0.2 gp_away | BF4: 0.4 f1_score_draw 0.3 expected_error 0.3 f1_score_away | BG4: error + gp_away | BJ4: error + acc_draw | BK4: f1_score + acc_draw | BL4: acc_draw + ex_acc_away | BM4: acc_draw + ex_acc_away + error | BN4: Expected_error + Error + gp_res | BO4: Expected_error + Error + gp_res (≠ pesos) | BP4: Expected_error + Error + gp_draw | BQ4: 1 Expected_error + 0 Error | BR4: expected_error': 0.7, 'expected_accuracy_away': 0.3 | BS4: expected_error': 0.7, 'accuracy_draw: 0.3 | BT4: 0.4 Expected_error 0.4 error 0.2 gp_draw 0.2 gp_away | BV4: accuracy_draw': 0.4, 'expected_accuracy_away': 0.4, 'expected_accuracy_draw': 0.2 | BW4: 0.4 Expected_error 0.4 error 0.2 gp_draw 0.2 gp_away | BX4: 0.47 expected_f1_score_away 0.29 f1_score_draw 0.24 expected_f1_score_home | BY4: 0.4 f1_score_draw 0.3 expected_error 0.3 f1_score_away | BZ4: error + gp_away | CE4: ger | CF4: -0.45602856 | CG4: -0.28873597 | CH4: -0.16092308 | CI4: -0.22411403
A5: Mean | B5: =AVERAGE(B7:B26) -> 3.398 | C5: =AVERAGE(C7:C26) -> 1.9915 | D5: =AVERAGE(D7:D26) -> 2.7805 | E5: =AVERAGE(E7:E26) -> 4.428 | F5: =AVERAGE(F7:F26) -> 3.961 | G5: =AVERAGE(G7:G26) -> 3.2711111 | H5: =AVERAGE(H7:H26) -> 4.0455 | I5: =AVERAGE(I7:I26) -> 3.589 | ... N5: =AVERAGE(N7:N26) -> 2.212 | P5: =AVERAGE(P7:P26) -> -8.158 | Q5: =AVERAGE(Q7:Q26) -> -10.9185 | R5: =AVERAGE(R7:R26) -> -8.707 | S5: =AVERAGE(S7:S26) -> -8.829 | T5: =AVERAGE(T7:T26) -> -9.1645 | U5: =AVERAGE(U7:U26) -> -8.655 | V5: =AVERAGE(V7:V26) -> -8.7705 | W5: =AVERAGE(W7:W26) -> -6.315 | Y5: =AVERAGE(Y7:Y26) -> -15.732 | Z5: =AVERAGE(Z7:Z26) -> -10.197 | AA5: =AVERAGE(AA7:AA26) -> -14.672 | AB5: =AVERAGE(AB7:AB26) -> -12.72 | AC5: =AVERAGE(AC7:AC26) -> -10.339 | AE5: =AVERAGE(AE7:AE26) -> 4.8415 | AF5: =AVERAGE(AF7:AF26) -> 4.8415 | AG5: =AVERAGE(AG7:AG26) -> 9.382 | AH5: =AVERAGE(AH7:AH26) -> 13.462 | AI5: =AVERAGE(AI7:AI26) -> 9.2985 | AJ5: =AVERAGE(AJ7:AJ26) -> 12.4525 | AK5: =AVERAGE(AK7:AK26) -> 13.307 | AL5: =AVERAGE(AL7:AL26) -> 11.1705 | AN5: =AVERAGE(AN7:AN26) -> -9.6785 | AO5: =AVERAGE(AO7:AO26) -> -2.638 | AP5: =AVERAGE(AP7:AP26) -> -4.056 | AQ5: =AVERAGE(AQ7:AQ26) -> -4.157 | AR5: =AVERAGE(AR7:AR26) -> 4.276 | AT5: =AVERAGE(AT7:AT26) -> 5.3195 | AU5: =AVERAGE(AU7:AU26) -> 4.796 | AV5: =AVERAGE(AV7:AV26) -> 6.309 | AW5: =AVERAGE(AW7:AW26) -> 7.104 | AX5: =AVERAGE(AX7:AX26) -> 7.126 | AY5: =AVERAGE(AY7:AY26) -> 4.5005 | AZ5: =AVERAGE(AZ7:AZ26) -> 6.8285 | BA5: =AVERAGE(BA7:BA26) -> 6.0595 | BB5: =AVERAGE(BB7:BB26) -> 4.9205 | BD5: =AVERAGE(BD7:BD26) -> 12.331 | BE5: =AVERAGE(BE7:BE26) -> 11.9455 | BF5: =AVERAGE(BF7:BF26) -> 11.9335 | BG5: =AVERAGE(BG7:BG26) -> 9.6705 | BH5: =AVERAGE(BH7:BH26) -> 11.4995 | BJ5: =AVERAGE(BJ7:BJ26) -> 11.582 | BK5: =AVERAGE(BK7:BK26) -> 13.931 | BL5: =AVERAGE(BL7:BL26) -> 19.261 | BM5: =AVERAGE(BM7:BM26) -> 17.1135 | BN5: =AVERAGE(BN7:BN26) -> 12.7565 | BO5: =AVERAGE(BO7:BO26) -> 11.1805 | BP5: =AVERAGE(BP7:BP26) -> 6.218 | BQ5: =AVERAGE(BQ7:BQ26) -> 10.122 | ... BT5: =AVERAGE(BT7:BT26) -> 15.445 | BV5: =AVERAGE(BV7:BV26) -> 17.4875 | BW5: =AVERAGE(BW7:BW26) -> 8.906 | BY5: =AVERAGE(BY7:BY26) -> 8.0635 | BZ5: =AVERAGE(BZ7:BZ26) -> 8.121 | CA5: =AVERAGE(CA7:CA26) -> 5.7788235 | CE5: ita | CF5: -0.57020319 | CG5: -0.51799341 | CH5: -0.25717265 | CI5: -0.49683768
A6: Var | B6: =STDEV(B7:B26) -> 8.3485704 | C6: =STDEV(C7:C26) -> 3.293637 | D6: =STDEV(D7:D26) -> 3.2869398 | E6: =STDEV(E7:E26) -> 8.6757864 | F6: =STDEV(F7:F26) -> 7.6969925 | G6: =STDEV(G7:G26) -> 5.9076938 | H6: =STDEV(H7:H26) -> 8.330772 | I6: =STDEV(I7:I26) -> 7.752736 | ... N6: =STDEV(N7:N26) -> 3.2495467 | P6: =STDEV(P7:P26) -> 5.4502019 | Q6: =STDEV(Q7:Q26) -> 4.4466194 | R6: =STDEV(R7:R26) -> 4.0873284 | S6: =STDEV(S7:S26) -> 4.5517075 | T6: =STDEV(T7:T26) -> 2.9275344 | U6: =STDEV(U7:U26) -> 4.3602867 | V6: =STDEV(V7:V26) -> 6.6298873 | W6: =STDEV(W7:W26) -> 5.4861294 | Y6: =STDEV(Y7:Y26) -> 4.2827679 | Z6: =STDEV(Z7:Z26) -> 8.4494404 | AA6: =STDEV(AA7:AA26) -> 5.9230207 | AB6: =STDEV(AB7:AB26) -> 5.8173099 | AC6: =STDEV(AC7:AC26) -> 9.303112 | AE6: =STDEV(AE7:AE26) -> 14.009586 | AF6: =STDEV(AF7:AF26) -> 14.009586 | AG6: =STDEV(AG7:AG26) -> 11.104749 | AH6: =STDEV(AH7:AH26) -> 12.338576 | AI6: =STDEV(AI7:AI26) -> 12.379091 | AJ6: =STDEV(AJ7:AJ26) -> 12.899004 | AK6: =STDEV(AK7:AK26) -> 18.459721 | AL6: =STDEV(AL7:AL26) -> 14.246473 | AN6: =STDEV(AN7:AN26) -> 8.9186182 | AO6: =STDEV(AO7:AO26) -> 10.845859 | AP6: =STDEV(AP7:AP26) -> 11.248087 | AQ6: =STDEV(AQ7:AQ26) -> 11.230538 | AR6: =STDEV(AR7:AR26) -> 11.45874 | AT6: =STDEV(AT7:AT26) -> 7.0680225 | AU6: =STDEV(AU7:AU26) -> 7.2171436 | AV6: =STDEV(AV7:AV26) -> 5.9554989 | AW6: =STDEV(AW7:AW26) -> 5.1624366 | AX6: =STDEV(AX7:AX26) -> 2.9292345 | AY6: =STDEV(AY7:AY26) -> 5.8458699 | AZ6: =STDEV(AZ7:AZ26) -> 3.9572362 | BA6: =STDEV(BA7:BA26) -> 6.7489465 | BB6: =STDEV(BB7:BB26) -> 7.3104744 | BD6: =STDEV(BD7:BD26) -> 7.4733575 | BE6: =STDEV(BE7:BE26) -> 7.6501899 | BF6: =STDEV(BF7:BF26) -> 8.2693259 | BG6: =STDEV(BG7:BG26) -> 8.1559152 | BH6: =STDEV(BH7:BH26) -> 7.7396834 | BJ6: =STDEV(BJ7:BJ26) -> 10.415495 | BK6: =STDEV(BK7:BK26) -> 12.968209 | BL6: =STDEV(BL7:BL26) -> 14.25319 | BM6: =STDEV(BM7:BM26) -> 16.035016 | BN6: =STDEV(BN7:BN26) -> 13.62926 | BO6: =STDEV(BO7:BO26) -> 10.348962 | BP6: =STDEV(BP7:BP26) -> 8.4057753 | BQ6: =STDEV(BQ7:BQ26) -> 11.207969 | ... BT6: =STDEV(BT7:BT26) -> 14.973117 | BV6: =STDEV(BV7:BV26) -> 14.133011 | BW6: =STDEV(BW7:BW26) -> 16.164112 | BY6: =STDEV(BY7:BY26) -> 17.925349 | BZ6: =STDEV(BZ7:BZ26) -> 15.866516 | CA6: =STDEV(CA7:CA26) -> 16.655175 | CE6: spa | CF6: -0.22139498 | CG6: -0.24963855 | CH6: -0.12799741 | CI6: -0.20803615
B7: 4.43 | C7: 1.1 | D7: 5.52 | E7: 33.5 | F7: -3.72 | G7: 1.1 | H7: 4.12 | I7: 1.1 | J7: 4.43 | K7: 33.5 | L7: 33.5 | M7: 33.5 | N7: 4.43 | P7: -6.53 | Q7: -15.02 | R7: -6.53 | S7: -15.09 | T7: -9.17 | U7: -9.17 | V7: -7.67 | W7: -6.38 | Y7: -19.22 | Z7: -13.08 | AA7: -23.67 | AB7: -19.11 | AC7: -19.16 | AE7: 13.2 | AF7: 13.2 | AG7: 13.2 | AH7: 22.68 | AI7: 22.39 | AJ7: 11.73 | AK7: -4.36 | AL7: -4.36 | AN7: -6.72 | AO7: -3.06 | AP7: -12.89 | AQ7: -6.72 | AR7: 12.39 | AT7: 5.89 | AU7: 16.19 | AV7: 5.89 | AW7: 5.75 | AX7: 5.75 | AY7: 16.24 | AZ7: 5.75 | BA7: 5.89 | BB7: 7.53 | BD7: 12.07 | BE7: 14.51 | BF7: 16.44 | BG7: 14.51 | BH7: 14.08 | BJ7: 9.62 | BK7: 39.03 | BL7: 9.17 | BM7: -2.79 | BN7: 13.3 | BO7: 14.98 | BP7: 9.62 | BQ7: 7.38 | BR7: 0.02 | BS7: 7.38 | BT7: 1.03 | BV7: 3.78 | BW7: -5.33 | BY7: 2.69 | BZ7: 1.33 | CA7: 1.33 | CE7: Mean | CF7: =AVERAGE(CF2:CF6) -> -0.45141735 | CG7: =AVERAGE(CG2:CG6) -> -0.35544959 | CH7: =AVERAGE(CH2:CH6) -> -0.15877723 | CI7: =AVERAGE(CI2:CI6) -> -0.35367357
